Workbook

Sheet Inputs
A1: Inputs - every number used by the model
A2: Blue cells are inputs; change them and every sheet recalculates. Green = DATA from 03, blue tint = BENCHMARK from 02b, yellow = ASSUMPTION (needs Finance or business confirmation). Single-value rows copy the Base value into Low and High. All money in USD.
A4: Key | B4: Input | C4: Low | D4: Base | E4: High | F4: Unit | G4: Type | H4: Source / note
A5: A. Internal baseline (TTM 2025-10-22 to 2026-10-21)
A6: rev_gross | B6: GCC gross revenue, incl VAT | C6: =D6 | D6: 13390000 | E6: =D6 | F6: USD/yr | G6: DATA | H6: 03-baseline-metrics.md, summary table, GCC total
A7: rev_soft | B7: Softline gross revenue, incl VAT | C7: =D7 | D7: 8460000 | E7: =D7 | F7: USD/yr | G7: DATA | H7: 03-baseline-metrics.md, summary table, softline total (9 brands)
A8: rev_hard | B8: Hardline gross revenue, incl VAT | C8: =D8 | D8: 4930000 | E8: =D8 | F8: USD/yr | G8: DATA | H8: 03-baseline-metrics.md, summary table, hardline total (9 brands)
A9: rev_net | B9: GCC net revenue after cancellations and returns, incl VAT | C9: =D9 | D9: 12040000 | E9: =D9 | F9: USD/yr | G9: DATA | H9: 03-baseline-metrics.md, summary table, GCC total net
A10: rev_soft_net | B10: Softline net revenue, incl VAT | C10: =D10 | D10: 7140000 | E10: =D10 | F10: USD/yr | G10: DATA | H10: 03-baseline-metrics.md, summary table, softline net
A11: ret_rate | B11: Cancellation plus return rate (value) = 1 - net/gross | C11: =D11 | D11: =1-D9/D6 | E11: =D11 | F11: % | G11: DATA | H11: Derived from the two rows above
A12: stock_asp | B12: Stock on hand, valued at selling price incl VAT | C12: =D12 | D12: 6480000 | E12: =D12 | F12: USD | G12: DATA | H12: 03-baseline-metrics.md, summary table (all unified_inventory sources)
A13: stock_units | B13: Stock on hand, units | C13: =D13 | D13: 155074 | E13: =D13 | F13: units | G13: DATA | H13: 03-baseline-metrics.md, summary table
A14: st_90d | B14: Sell-through, last 90 days (GCC) | C14: =D14 | D14: 0.4 | E14: =D14 | F14: % | G14: DATA | H14: 03-baseline-metrics.md, summary table
A15: aged180 | B15: Stock value over 180 days since receipt (upper bound proxy) | C15: =D15 | D15: 2690000 | E15: =D15 | F15: USD | G15: DATA | H15: 03-baseline-metrics.md, ageing table, GCC total; caveat 5 says upper bound
A16: lost_daily | B16: Stock-out proxy, softline demand on zero-stock SKU-locations (upper bound) | C16: =D16 | D16: 6666 | E16: =D16 | F16: USD/day | G16: DATA | H16: 03-baseline-metrics.md, stock and stock-out table, softline total
A17: lost_anchor | B17: Stock-out proxy, lower anchor (locations selling 0.2+ units a day) | C17: =D17 | D17: 1376 | E17: =D17 | F17: USD/day | G17: DATA | H17: 03-baseline-metrics.md, split of stock-out proxy (query R1b)
A18: sizefit | B18: Namshi size or fit returns, at listing price | C18: =D18 | D18: 682000 | E18: =D18 | F18: USD/yr | G18: DATA | H18: 03-baseline-metrics.md, returns section (DD9 method)
A19: g_soft | B19: Softline unit growth, last 6 months vs previous 6 | C19: =D19 | D19: 0.25 | E19: =D19 | F19: % | G19: DATA | H19: 03-baseline-metrics.md, summary table; includes launches
A20: g_gcc | B20: GCC unit growth, last 6 months vs previous 6 | C20: =D20 | D20: 0.49 | E20: =D20 | F20: % | G20: DATA | H20: 03-baseline-metrics.md, summary table; includes brand launches and new channels
A21: g_uspa | B21: U.S. Polo Assn. unit growth, last 6 months vs previous 6 (closest to like-for-like) | C21: =D21 | D21: -0.01 | E21: =D21 | F21: % | G21: DATA | H21: 03-baseline-metrics.md, summary table
A22: B. Financial assumptions
A23: vat | B23: Blended VAT rate in gross revenue (UAE 5%, KSA 15%) | C23: =D23 | D23: 0.1 | E23: =D23 | F23: % | G23: ASSUMPTION | H23: Country mix not in 03; about half KSA assumed. Gross is incl VAT (03 definitions)
A24: gm | B24: Gross margin, % of net revenue ex VAT (price minus landed cost) | C24: 0.35 | D24: 0.4 | E24: 0.45 | F24: % | G24: ASSUMPTION | H24: Brand distributor on marketplaces; no unit cost usable in the warehouse (03 caveat 6). Finance to confirm
A25: var_cost | B25: Variable selling cost on extra sales (marketplace commission share, fulfilment), % of net ex VAT | C25: =D25 | D25: 0.15 | E25: =D25 | F25: % | G25: ASSUMPTION | H25: Conservative; recovered sales valued at gross margin less this
A26: coc | B26: Cost of capital, used to value cash tied in stock | C26: 0.1 | D26: 0.12 | E26: 0.15 | F26: %/yr | G26: ASSUMPTION | H26: Typical GCC/India mid-size company WACC; Finance to confirm
A27: dr | B27: Discount rate for NPV | C27: =D27 | D27: 0.12 | E27: =D27 | F27: %/yr | G27: ASSUMPTION | H27: Set equal to cost of capital base
A28: md_pct | B28: Markdown and ageing write-down cost borne by Opptra, % of net revenue ex VAT | C28: 0.06 | D28: 0.1 | E28: 0.15 | F28: % | G28: ASSUMPTION | H28: 02b B3 illustrates 15-25% of gross sales and 05 uses 20%; kept lower because marketplaces fund part of promotions. Cross-check: aged stock row on Levers
A29: clear_disc | B29: Clearance discount on stock over 180 days (cross-check only) | C29: =D29 | D29: 0.4 | E29: =D29 | F29: % | G29: ASSUMPTION | H29: Used only to sanity-check md_pct
A30: ret_handling | B30: Cost of handling one returned USD (reverse logistics, marketplace return fees, damage) | C30: =D30 | D30: 0.15 | E30: =D30 | F30: % | G30: ASSUMPTION | H30: No GCC figure in 02b A5; Finance to confirm from Namshi settlement reports
A31: keep_share | B31: Share of avoided size returns that become kept sales | C31: =D31 | D31: 0.5 | E31: =D31 | F31: % | G31: ASSUMPTION | H31: Rest are orders that simply do not happen
A32: hard_factor | B32: Hardline stock-out intensity vs softline (per USD of revenue) | C32: =D32 | D32: 0.5 | E32: =D32 | F32: x | G32: ASSUMPTION | H32: Replen run covers softline only (03 caveat 9); hardline has few SKUs and 48% sell-through, so assumed half
A33: planners | B33: People doing forecasting and buy planning (FTE) | C33: =D33 | D33: 4 | E33: =D33 | F33: FTE | G33: ASSUMPTION | H33: Ashish, Mahesh plus buyers/brand managers (06 section 4)
A34: planner_cost | B34: Loaded cost per planner, GCC | C34: =D34 | D34: 55000 | E34: =D34 | F34: USD/yr | G34: ASSUMPTION | H34: 05 section 4.1, GCC planning analyst loaded rate
A35: manual_share | B35: Share of planner time spent on manual forecasting and spreadsheet buy plans | C35: =D35 | D35: 0.3 | E35: =D35 | F35: % | G35: ASSUMPTION | H35: Not measured; check in Phase 0
A36: new_share | B36: Share of softline revenue from styles in their first season | C36: =D36 | D36: 0.3 | E36: =D36 | F36: % | G36: ASSUMPTION | H36: 03 new-styles table shows steady new-style drops; not measured as revenue
A37: uplift_pt | B37: Revenue uplift on new styles per hit-rate point | C37: =D37 | D37: 0.01 | E37: =D37 | F37: %/pt | G37: ASSUMPTION | H37: 1 point more hits = 1% more new-style revenue
A38: growth_cap | B38: Cap on annual growth used in Growth sheet | C38: =D38 | D38: 0.1 | E38: =D38 | F38: %/yr | G38: ASSUMPTION | H38: Conservative cap; observed unit growth is mostly launches (03 caveat 2)
A39: cost_mult | B39: Cost multiplier on 05 Option D cost | C39: 1.22 | D39: 1 | E39: 1 | F39: x | G39: ASSUMPTION | H39: Low = top of 05 range (USD 832k / 680k); high case does not assume cheaper delivery
A40: ramp1 | B40: Adoption / realisation, year 1 (pilot first) | C40: 0.25 | D40: 0.3 | E40: 0.4 | F40: % | G40: ASSUMPTION | H40: 05 section 5 ramp 30/70/100; pilot Dec 2026 - Apr 2027 on 3 brands (06 section 11)
A41: ramp2 | B41: Adoption / realisation, year 2 | C41: 0.55 | D41: 0.7 | E41: 0.85 | F41: % | G41: ASSUMPTION | H41: 05 section 5
...

Sheet Levers
A1: Levers - how each benefit is calculated (Low / Base / High)
A2: Every cell is a formula on Inputs and Costs. Annual benefit = steady state at full adoption on today's revenue. One-off cash release and NPD upside (f) are shown but never added to the annual benefit.
A4: Step | C4: Low | D4: Base | E4: High | F4: How
A5: Common
A6: VAT divisor (1 + VAT) | C6: =1+Inputs!$C$23 | D6: =1+Inputs!$D$23 | E6: =1+Inputs!$E$23 | F6: Strips VAT from gross numbers
A7: Net revenue ex VAT | C7: =Inputs!$C$9/C6 | D7: =Inputs!$D$9/D6 | E7: =Inputs!$E$9/E6
A8: Contribution margin on extra sales | C8: =Inputs!$C$24-Inputs!$C$25 | D8: =Inputs!$D$24-Inputs!$D$25 | E8: =Inputs!$E$24-Inputs!$E$25 | F8: Gross margin less variable selling cost
A9: (a) Recovered lost sales from fewer stock-outs
A10: Softline lost demand a year (gross) | C10: =Inputs!$C$16*365*Inputs!$C$49 | D10: =Inputs!$D$16*365*Inputs!$D$49 | E10: =Inputs!$E$16*365*Inputs!$E$49 | F10: Stock-out proxy x 365 x realisable share
A11: Hardline lost demand a year (gross) | C11: =C10/Inputs!$C$7*Inputs!$C$8*Inputs!$C$32 | D11: =D10/Inputs!$D$7*Inputs!$D$8*Inputs!$D$32 | E11: =E10/Inputs!$E$7*Inputs!$E$8*Inputs!$E$32 | F11: Softline intensity x hardline revenue x hardline factor
A12: Total lost demand a year (gross) | C12: =C10+C11 | D12: =D10+D11 | E12: =E10+E11
A13: Recovered sales before cap | C13: =C12*Inputs!$C$48 | D13: =D12*Inputs!$D$48 | E13: =E12*Inputs!$E$48 | F13: Pool x lost-sales reduction
A14: Cap: revenue x total sales lift | C14: =Inputs!$C$6*Inputs!$C$50 | D14: =Inputs!$D$6*Inputs!$D$50 | E14: =Inputs!$E$6*Inputs!$E$50 | F14: 02b sales-lift ceiling
A15: Recovered gross sales (lower of the two) | C15: =MIN(C13,C14) | D15: =MIN(D13,D14) | E15: =MIN(E13,E14)
A16: (a) Value: recovered sales at contribution margin | C16: =C15/C6*(1-Inputs!$C$11)*C8 | D16: =D15/D6*(1-Inputs!$D$11)*D8 | E16: =E15/E6*(1-Inputs!$E$11)*E8 | F16: Ex VAT, net of returns, x contribution
A17: (b) Working capital released from lower inventory
A18: Stock at cost, ex VAT | C18: =Inputs!$C$12/C6*(1-Inputs!$C$24) | D18: =Inputs!$D$12/D6*(1-Inputs!$D$24) | E18: =Inputs!$E$12/E6*(1-Inputs!$E$24) | F18: Selling-price value -> cost
A19: One-off cash release at full adoption (shown separately) | C19: =C18*Inputs!$C$51 | D19: =D18*Inputs!$D$51 | E19: =E18*Inputs!$E$51 | F19: NOT in annual benefit
A20: (b) Value: annual carrying saving on released cash | C20: =C19*Inputs!$C$26 | D20: =D19*Inputs!$D$26 | E20: =E19*Inputs!$E$26 | F20: Cash release x cost of capital
A21: (c) Markdown and ageing write-down avoided
A22: Markdown and write-down cost a year | C22: =C7*Inputs!$C$28 | D22: =D7*Inputs!$D$28 | E22: =E7*Inputs!$E$28 | F22: Net ex VAT x markdown share
A23: Cross-check: stock over 180 days x clearance discount, ex VAT | C23: =Inputs!$C$15/C6*Inputs!$C$29 | D23: =Inputs!$D$15/D6*Inputs!$D$29 | E23: =Inputs!$E$15/E6*Inputs!$E$29 | F23: Should be the same order as the row above
A24: (c) Value: markdown and write-down avoided | C24: =C22*Inputs!$C$52 | D24: =D22*Inputs!$D$52 | E24: =E22*Inputs!$E$52
A25: (d) Size-curve improvement: fewer size or fit returns
A26: Size or fit returns a year, ex VAT | C26: =Inputs!$C$18/C6 | D26: =Inputs!$D$18/D6 | E26: =Inputs!$E$18/E6 | F26: USD 682k base
A27: (d) Value: handling cost avoided plus margin on kept sales | C27: =C26*Inputs!$C$54*(Inputs!$C$30+Inputs!$C$31*C8) | D27: =D26*Inputs!$D$54*(Inputs!$D$30+Inputs!$D$31*D8) | E27: =E26*Inputs!$E$54*(Inputs!$E$30+Inputs!$E$31*E8)
A28: (e) Planner time saved
A29: (e) Value: planner capacity freed | C29: =Inputs!$C$33*Inputs!$C$34*Inputs!$C$35*Inputs!$C$55 | D29: =Inputs!$D$33*Inputs!$D$34*Inputs!$D$35*Inputs!$D$55 | E29: =Inputs!$E$33*Inputs!$E$34*Inputs!$E$35*Inputs!$E$55 | F29: Capacity, not a headcount cut
A30: Total annual benefit (steady state, current revenue base)
A31: Sum of levers a to e | C31: =C16+C20+C24+C27+C29 | D31: =D16+D20+D24+D27+D29 | E31: =E16+E20+E24+E27+E29
A32: Less overlap haircut on a+b+c | C32: =-(C16+C20+C24)*Inputs!$C$43 | D32: =-(D16+D20+D24)*Inputs!$D$43 | E32: =-(E16+E20+E24)*Inputs!$E$43 | F32: 02b B2: levers trade off
A33: ANNUAL BENEFIT at full adoption | C33: =C31+C32 | D33: =D31+D32 | E33: =E31+E32 | F33: Excludes NPD (f) and one-off cash
A34: (f) NPD upside - shown separately, EXCLUDED from all totals
A35: (f) NPD hit-rate upside a year | C35: =Inputs!$C$10/C6*Inputs!$C$36*Inputs!$C$56*Inputs!$C$37*C8 | D35: =Inputs!$D$10/D6*Inputs!$D$36*Inputs!$D$56*Inputs!$D$37*D8 | E35: =Inputs!$E$10/E6*Inputs!$E$36*Inputs!$E$56*Inputs!$E$37*E8 | F35: Upside only
A36: Cross-check against the sell-through benchmark
A37: Units sold in 90 days implied by today's sell-through | C37: =Inputs!$C$13*Inputs!$C$14/(1-Inputs!$C$14) | D37: =Inputs!$D$13*Inputs!$D$14/(1-Inputs!$D$14) | E37: =Inputs!$E$13*Inputs!$E$14/(1-Inputs!$E$14)
A38: Sell-through after recovered sales and lower stock | C38: =C37*(1+C15/Inputs!$C$6)/(C37*(1+C15/Inputs!$C$6)+Inputs!$C$13*(1-Inputs!$C$51)) | D38: =D37*(1+D15/Inputs!$D$6)/(D37*(1+D15/Inputs!$D$6)+Inputs!$D$13*(1-Inputs!$D$51)) | E38: =E37*(1+E15/Inputs!$E$6)/(E37*(1+E15/Inputs!$E$6)+Inputs!$E$13*(1-Inputs!$E$51))
A39: Implied sell-through change, points (02b benchmark in Inputs st_pts) | C39: =(C38-Inputs!$C$14)*100 | D39: =(D38-Inputs!$D$14)*100 | E39: =(E38-Inputs!$E$14)*100 | F39: Should sit near the benchmark
A40: Three-year view (ramp-up applied)
A41: Benefit Y1 | C41: =C33*Inputs!$C$40 | D41: =D33*Inputs!$D$40 | E41: =E33*Inputs!$E$40
...

Sheet Costs
A1: Costs - Option D (hybrid, staged), from 05-build-vs-buy.md section 4.5
A2: Rates and months are inputs (blue). They rebuild 05's totals (USD 191.6k / 238.4k / 250.2k = 680.2k). Year 1 = Nov 2026 - Oct 2027. Phase dates from 06 section 11. Business time is not in 05; it is added below as an ASSUMPTION so the ROI is not flattered. Scenario cost multiplier is on Inputs.
A4: Phase | B4: People cost rate (USD/yr) | C4: GCP (USD/month) | D4: Data and licences (USD/month) | E4: One-off (USD) | F4: Months in Y1 | G4: Months in Y2 | H4: Months in Y3 | I4: Source
A5: Phase 0 - Prove the basics (9 Nov - 18 Dec 2026) | B5: 97000 | C5: 200 | D5: 0 | E5: 500 | F5: 1.5 | G5: 0 | H5: 0 | I5: 05 4.5 FTE table; one-off = capped Cardio Bunny scrape
A6: Phase 1 - Pilot, 3 brands, Ramadan 2027 (21 Dec 2026 - 30 Apr 2027) | B6: 151500 | C6: 300 | D6: 1000 | E6: 0 | F6: 4.5 | G6: 0 | H6: 0 | I6: 05 4.5
A7: Phase 2 - Scale to all brands (May - Dec 2027) | B7: 202000 | C7: 500 | D7: 2000 | E7: 0 | F7: 6 | G7: 2 | H7: 0 | I7: 05 4.5
A8: Phase 3 - Own product (from Jan 2028; Y3 incl 0.5 partner success) | B8: 208500 | C8: 600 | D8: 2000 | E8: 0 | F8: 0 | G8: 10 | H8: 0 | I8: 05 4.5
A9: Phase 3 - year 3 rate | B9: 219000 | C9: 600 | D9: 2000 | E9: 0 | F9: 0 | G9: 0 | H9: 12 | I9: 05 4.5 (219.0k incl partner success)
A11: Business time not costed in 05 (ASSUMPTION)
A12: Hours a week (Ashish, Mahesh 2-3 h each; Nitin 2 h; 3 pilot brand managers 2 h each; 06 section 12) | B12: 12
A13: Working weeks a year | B13: 46
A14: Loaded hourly cost, GCC staff (USD 55k / 1,840 h, 05 4.1 analyst rate) | B14: =55000/1840
A15: Include business time in ROI cost? (1 = yes, 0 = no) | B15: 1
A17: Cost by year, per phase (USD)
A18: Line | B18: Y1 | C18: Y2 | D18: Y3 | E18: 3 years
A19: Phase 0 - Prove the basics (9 Nov - 18 Dec 2026) | B19: =$B5*F5/12+($C5+$D5)*F5+$E5 | C19: =$B5*G5/12+($C5+$D5)*G5 | D19: =$B5*H5/12+($C5+$D5)*H5 | E19: =SUM(B19:D19)
A20: Phase 1 - Pilot, 3 brands, Ramadan 2027 (21 Dec 2026 - 30 Apr 2027) | B20: =$B6*F6/12+($C6+$D6)*F6+$E6 | C20: =$B6*G6/12+($C6+$D6)*G6 | D20: =$B6*H6/12+($C6+$D6)*H6 | E20: =SUM(B20:D20)
A21: Phase 2 - Scale to all brands (May - Dec 2027) | B21: =$B7*F7/12+($C7+$D7)*F7+$E7 | C21: =$B7*G7/12+($C7+$D7)*G7 | D21: =$B7*H7/12+($C7+$D7)*H7 | E21: =SUM(B21:D21)
A22: Phase 3 - Own product (from Jan 2028; Y3 incl 0.5 partner success) | B22: =$B8*F8/12+($C8+$D8)*F8+$E8 | C22: =$B8*G8/12+($C8+$D8)*G8 | D22: =$B8*H8/12+($C8+$D8)*H8 | E22: =SUM(B22:D22)
A23: Phase 3 - year 3 rate | B23: =$B9*F9/12+($C9+$D9)*F9+$E9 | C23: =$B9*G9/12+($C9+$D9)*G9 | D23: =$B9*H9/12+($C9+$D9)*H9 | E23: =SUM(B23:D23)
A24: Subtotal, 05 Option D | B24: =SUM(B19:B23) | C24: =SUM(C19:C23) | D24: =SUM(D19:D23) | E24: =SUM(E19:E23)
A25: Check against 05 (USD 191.6k / 238.4k / 250.2k / 680.2k) | B25: 191600 | C25: 238400 | D25: 250200 | E25: 680200
A26: Business time (ASSUMPTION, added) | B26: =$B$12*$B$13*$B$14*$B$15 | C26: =$B$12*$B$13*$B$14*$B$15 | D26: =$B$12*$B$13*$B$14*$B$15 | E26: =SUM(B26:D26)
A27: Total cost used in ROI (before scenario multiplier) | B27: =B24+B26 | C27: =C24+C26 | D27: =D24+D26 | E27: =E24+E26
A29: Same cost by type (USD)
A30: Line | B30: Y1 | C30: Y2 | D30: Y3 | E30: 3 years
A31: People | B31: =$B5*F5/12+$B6*F6/12+$B7*F7/12+$B8*F8/12+$B9*F9/12 | C31: =$B5*G5/12+$B6*G6/12+$B7*G7/12+$B8*G8/12+$B9*G9/12 | D31: =$B5*H5/12+$B6*H6/12+$B7*H7/12+$B8*H8/12+$B9*H9/12 | E31: =SUM(B31:D31)
A32: GCP | B32: =$C5*F5+$C6*F6+$C7*F7+$C8*F8+$C9*F9 | C32: =$C5*G5+$C6*G6+$C7*G7+$C8*G8+$C9*G9 | D32: =$C5*H5+$C6*H6+$C7*H7+$C8*H8+$C9*H9 | E32: =SUM(B32:D32)
A33: Data and licences | B33: =$D5*F5+$D6*F6+$D7*F7+$D8*F8+$D9*F9+$E5+$E6+$E7+$E8+$E9 | C33: =$D5*G5+$D6*G6+$D7*G7+$D8*G8+$D9*G9 | D33: =$D5*H5+$D6*H6+$D7*H7+$D8*H8+$D9*H9 | E33: =SUM(B33:D33)
A34: Business time | B34: =B26 | C34: =C26 | D34: =D26 | E34: =E26

Sheet Scenarios
A1: Scenarios - low / base / high
A2: Low uses every low input at once (and costs at the top of 05's range), so it is a stress case, not a likely case. Payback counts months from 9 Nov 2026 until cumulative benefit minus cost turns positive.
A4: Result | C4: Low | D4: Base | E4: High
A5: Annual benefit, full adoption (current revenue base) | C5: =Levers!$C$33 | D5: =Levers!$D$33 | E5: =Levers!$E$33
A6: of which (a) recovered lost sales | C6: =Levers!$C$16 | D6: =Levers!$D$16 | E6: =Levers!$E$16
A7: of which (b) carrying saving on released stock | C7: =Levers!$C$20 | D7: =Levers!$D$20 | E7: =Levers!$E$20
A8: of which (c) markdown and write-down avoided | C8: =Levers!$C$24 | D8: =Levers!$D$24 | E8: =Levers!$E$24
A9: of which (d) fewer size or fit returns | C9: =Levers!$C$27 | D9: =Levers!$D$27 | E9: =Levers!$E$27
A10: of which (e) planner time | C10: =Levers!$C$29 | D10: =Levers!$D$29 | E10: =Levers!$E$29
A11: less overlap haircut | C11: =Levers!$C$32 | D11: =Levers!$D$32 | E11: =Levers!$E$32
A12: Benefit Y1 (pilot year, ramp applied) | C12: =Levers!$C$41 | D12: =Levers!$D$41 | E12: =Levers!$E$41
A13: Benefit Y2 | C13: =Levers!$C$42 | D13: =Levers!$D$42 | E13: =Levers!$E$42
A14: Benefit Y3 | C14: =Levers!$C$43 | D14: =Levers!$D$43 | E14: =Levers!$E$43
A15: Cost Y1 | C15: =Levers!$C$44 | D15: =Levers!$D$44 | E15: =Levers!$E$44
A16: Cost Y2 | C16: =Levers!$C$45 | D16: =Levers!$D$45 | E16: =Levers!$E$45
A17: Cost Y3 | C17: =Levers!$C$46 | D17: =Levers!$D$46 | E17: =Levers!$E$46
A18: 3-year NPV, excl one-off cash release | C18: =Levers!$C$52 | D18: =Levers!$D$52 | E18: =Levers!$E$52
A19: ROI multiple (PV benefits / PV costs) | C19: =Levers!$C$53 | D19: =Levers!$D$53 | E19: =Levers!$E$53
A20: One-off cash released from stock (full adoption) | C20: =Levers!$C$19 | D20: =Levers!$D$19 | E20: =Levers!$E$19
A21: 3-year NPV incl one-off cash release | C21: =Levers!$C$57 | D21: =Levers!$D$57 | E21: =Levers!$E$57
A22: NPD upside a year (excluded above) | C22: =Levers!$C$35 | D22: =Levers!$D$35 | E22: =Levers!$E$35
A23: 3-year benefit / 3-year cost, undiscounted | C23: =(C12+C13+C14)/(C15+C16+C17) | D23: =(D12+D13+D14)/(D15+D16+D17) | E23: =(E12+E13+E14)/(E15+E16+E17)
A24: Payback month, excl cash release (months from start) | C24: =IF(MIN(C46:AL46)=999,"Not in 36 months",MIN(C46:AL46)) | D24: =IF(MIN(C52:AL52)=999,"Not in 36 months",MIN(C52:AL52)) | E24: =IF(MIN(C58:AL58)=999,"Not in 36 months",MIN(C58:AL58))
A25: Payback month, incl cash release | C25: =IF(MIN(C49:AL49)=999,"Not in 36 months",MIN(C49:AL49)) | D25: =IF(MIN(C55:AL55)=999,"Not in 36 months",MIN(C55:AL55)) | E25: =IF(MIN(C61:AL61)=999,"Not in 36 months",MIN(C61:AL61))
A26: Annual benefit needed at full adoption for NPV = 0 (break-even) | C26: =Levers!$C$51/(Inputs!$C$40/(1+Inputs!$C$27)+Inputs!$C$41/(1+Inputs!$C$27)^2+Inputs!$C$42/(1+Inputs!$C$27)^3) | D26: =Levers!$D$51/(Inputs!$D$40/(1+Inputs!$D$27)+Inputs!$D$41/(1+Inputs!$D$27)^2+Inputs!$D$42/(1+Inputs!$D$27)^3) | E26: =Levers!$E$51/(Inputs!$E$40/(1+Inputs!$E$27)+Inputs!$E$41/(1+Inputs!$E$27)^2+Inputs!$E$42/(1+Inputs!$E$27)^3)
A28: Stage-gated scenario (base inputs): leadership funds only Phases 0-1 until Gate 1 is met
A29: Phase 0 cost (05) | D29: =Costs!B19*Inputs!$D$39
A30: Phase 1 cost (05) | D30: =Costs!B20*Inputs!$D$39
A31: Business time during Phases 0-1 (6 of 12 months, ASSUMPTION) | D31: =Costs!B26*6/12
A32: CASH AT RISK before the Gate 1 go / no-go | D32: =D29+D30+D31
A33: Benefit counted before Gate 1 (Inputs pilot_ben) | D33: =Inputs!$D$45
A34: NPV if Gate 1 fails and work stops (spent in year 1) | D34: =(D33-D32)/(1+Inputs!$D$27)
A35: NPV if Gate 1 passes and Phases 2-3 go ahead (= base NPV) | D35: =Levers!$D$52
A36: Probability Gate 1 passes (Inputs p_gate1) | D36: =Inputs!$D$44
A37: Expected NPV, stage-gated | D37: =D36*D35+(1-D36)*D34
A38: Expected NPV if all 3 years were funded up front (no stop option; a failed product still costs all 3 years) | D38: =D36*D35+(1-D36)*(-Levers!$D$51)
A39: Value of stage-gating (difference) | D39: =D37-D38
A42: Monthly schedule (annual figures spread evenly within each year)
A43: Month | C43: 1 | D43: 2 | E43: 3 | F43: 4 | G43: 5 | H43: 6 | I43: 7 | J43: 8 | K43: 9 | L43: 10 | M43: 11 | N43: 12 | O43: 13 | P43: 14 | Q43: 15 | R43: 16 | S43: 17 | T43: 18 | U43: 19 | V43: 20 | W43: 21 | X43: 22 | Y43: 23 | Z43: 24 | AA43: 25 | AB43: 26 | AC43: 27 | AD43: 28 | AE43: 29 | AF43: 30 | AG43: 31 | AH43: 32 | AI43: 33 | AJ43: 34 | AK43: 35 | AL43: 36
A44: Low: net a month | C44: =(Levers!$C$41-Levers!$C$44)/12 | D44: =(Levers!$C$41-Levers!$C$44)/12 | E44: =(Levers!$C$41-Levers!$C$44)/12 | F44: =(Levers!$C$41-Levers!$C$44)/12 | G44: =(Levers!$C$41-Levers!$C$44)/12 | H44: =(Levers!$C$41-Levers!$C$44)/12 | I44: =(Levers!$C$41-Levers!$C$44)/12 | J44: =(Levers!$C$41-Levers!$C$44)/12 | ... N44: =(Levers!$C$41-Levers!$C$44)/12 | O44: =(Levers!$C$42-Levers!$C$45)/12 | P44: =(Levers!$C$42-Levers!$C$45)/12 | Q44: =(Levers!$C$42-Levers!$C$45)/12 | R44: =(Levers!$C$42-Levers!$C$45)/12 | S44: =(Levers!$C$42-Levers!$C$45)/12 | T44: =(Levers!$C$42-Levers!$C$45)/12 | U44: =(Levers!$C$42-Levers!$C$45)/12 | V44: =(Levers!$C$42-Levers!$C$45)/12 | ... Z44: =(Levers!$C$42-Levers!$C$45)/12 | AA44: =(Levers!$C$43-Levers!$C$46)/12 | AB44: =(Levers!$C$43-Levers!$C$46)/12 | AC44: =(Levers!$C$43-Levers!$C$46)/12 | AD44: =(Levers!$C$43-Levers!$C$46)/12 | AE44: =(Levers!$C$43-Levers!$C$46)/12 | AF44: =(Levers!$C$43-Levers!$C$46)/12 | AG44: =(Levers!$C$43-Levers!$C$46)/12 | AH44: =(Levers!$C$43-Levers!$C$46)/12 | ... AL44: =(Levers!$C$43-Levers!$C$46)/12
...

Sheet Growth
A1: Growth - benefit on today's revenue vs a grown revenue base
A2: Revenue-linked levers (a, b, c, d and the haircut) grow with revenue; planner time (e) does not. Growth rate = the lower of observed softline unit growth (03) and the cap on Inputs. Year 1 stays on today's base (conservative), so year n uses (1+g)^(n-1). Costs are the same in both views.
A4: Observed softline unit growth (03) | C4: =Inputs!$D$19
A5: Cap (Inputs) | C5: =Inputs!$D$38
A6: Growth rate used | C6: =MAX(0,MIN(C4,C5))
A7: Note: GCC unit growth (+49%) and USPA like-for-like (-1%) are on Inputs; the cap keeps launches out.
A9: Line | C9: Low | D9: Base | E9: High
A10: Benefit Y1, current base | C10: =Levers!$C$41 | D10: =Levers!$D$41 | E10: =Levers!$E$41
A11: Benefit Y2, current base | C11: =Levers!$C$42 | D11: =Levers!$D$42 | E11: =Levers!$E$42
A12: Benefit Y3, current base | C12: =Levers!$C$43 | D12: =Levers!$D$43 | E12: =Levers!$E$43
A13: Benefit Y1, grown base | C13: =((Levers!$C$33-Levers!$C$29)*(1+$C$6)^0+Levers!$C$29)*Inputs!$C$40 | D13: =((Levers!$D$33-Levers!$D$29)*(1+$C$6)^0+Levers!$D$29)*Inputs!$D$40 | E13: =((Levers!$E$33-Levers!$E$29)*(1+$C$6)^0+Levers!$E$29)*Inputs!$E$40
A14: Benefit Y2, grown base | C14: =((Levers!$C$33-Levers!$C$29)*(1+$C$6)^1+Levers!$C$29)*Inputs!$C$41 | D14: =((Levers!$D$33-Levers!$D$29)*(1+$C$6)^1+Levers!$D$29)*Inputs!$D$41 | E14: =((Levers!$E$33-Levers!$E$29)*(1+$C$6)^1+Levers!$E$29)*Inputs!$E$41
A15: Benefit Y3, grown base | C15: =((Levers!$C$33-Levers!$C$29)*(1+$C$6)^2+Levers!$C$29)*Inputs!$C$42 | D15: =((Levers!$D$33-Levers!$D$29)*(1+$C$6)^2+Levers!$D$29)*Inputs!$D$42 | E15: =((Levers!$E$33-Levers!$E$29)*(1+$C$6)^2+Levers!$E$29)*Inputs!$E$42
A16: 3-year NPV, current base | C16: =Levers!$C$52 | D16: =Levers!$D$52 | E16: =Levers!$E$52
A17: 3-year NPV, grown base | C17: =(C13-Levers!$C$44)/(1+Inputs!$C$27)+(C14-Levers!$C$45)/(1+Inputs!$C$27)^2+(C15-Levers!$C$46)/(1+Inputs!$C$27)^3 | D17: =(D13-Levers!$D$44)/(1+Inputs!$D$27)+(D14-Levers!$D$45)/(1+Inputs!$D$27)^2+(D15-Levers!$D$46)/(1+Inputs!$D$27)^3 | E17: =(E13-Levers!$E$44)/(1+Inputs!$E$27)+(E14-Levers!$E$45)/(1+Inputs!$E$27)^2+(E15-Levers!$E$46)/(1+Inputs!$E$27)^3
A18: ROI multiple, grown base | C18: =(C13/(1+Inputs!$C$27)+C14/(1+Inputs!$C$27)^2+C15/(1+Inputs!$C$27)^3)/Levers!$C$51 | D18: =(D13/(1+Inputs!$D$27)+D14/(1+Inputs!$D$27)^2+D15/(1+Inputs!$D$27)^3)/Levers!$D$51 | E18: =(E13/(1+Inputs!$E$27)+E14/(1+Inputs!$E$27)^2+E15/(1+Inputs!$E$27)^3)/Levers!$E$51
A19: Annual benefit at full adoption in Y3, grown base | C19: =(Levers!$C$33-Levers!$C$29)*(1+$C$6)^2+Levers!$C$29 | D19: =(Levers!$D$33-Levers!$D$29)*(1+$C$6)^2+Levers!$D$29 | E19: =(Levers!$E$33-Levers!$E$29)*(1+$C$6)^2+Levers!$E$29

Sheet Sensitivity
A1: Sensitivity - tornado on 3-year NPV (one driver at a time, others at base)
A2: Each driver is moved to its Low and High input while all others stay at Base. Rows are ordered by swing at build time; the Rank column recalculates if inputs change. The top 5 are the drivers to test in the pilot. The calculation block below repeats the full Levers chain for every run.
A4: Driver | B4: Low input | C4: High input | D4: NPV at low input | E4: NPV at high input | F4: Base NPV | G4: Swing (abs) | H4: Rank | I4: Top 5?
A5: Markdown reduction (md_red) | B5: =Inputs!$C$52 | C5: =Inputs!$E$52 | D5: =B70 | E5: =C70 | F5: =Levers!$D$52 | G5: =ABS(E5-D5) | H5: =COUNTIF($G$5:$G$17,">"&G5)+1 | I5: =IF(H5<=5,"TOP 5","")
A6: Cost multiplier | B6: =Inputs!$C$39 | C6: =Inputs!$E$39 | D6: =D70 | E6: =E70 | F6: =Levers!$D$52 | G6: =ABS(E6-D6) | H6: =COUNTIF($G$5:$G$17,">"&G6)+1 | I6: =IF(H6<=5,"TOP 5","")
A7: Markdown cost share (md_pct) | B7: =Inputs!$C$28 | C7: =Inputs!$E$28 | D7: =F70 | E7: =G70 | F7: =Levers!$D$52 | G7: =ABS(E7-D7) | H7: =COUNTIF($G$5:$G$17,">"&G7)+1 | I7: =IF(H7<=5,"TOP 5","")
A8: Adoption ramp Y1-Y3 | B8: =Inputs!$C$40 | C8: =Inputs!$E$40 | D8: =H70 | E8: =I70 | F8: =Levers!$D$52 | G8: =ABS(E8-D8) | H8: =COUNTIF($G$5:$G$17,">"&G8)+1 | I8: =IF(H8<=5,"TOP 5","")
A9: Lost-sales reduction (ls_red) | B9: =Inputs!$C$48 | C9: =Inputs!$E$48 | D9: =J70 | E9: =K70 | F9: =Levers!$D$52 | G9: =ABS(E9-D9) | H9: =COUNTIF($G$5:$G$17,">"&G9)+1 | I9: =IF(H9<=5,"TOP 5","")
A10: Overlap haircut | B10: =Inputs!$C$43 | C10: =Inputs!$E$43 | D10: =L70 | E10: =M70 | F10: =Levers!$D$52 | G10: =ABS(E10-D10) | H10: =COUNTIF($G$5:$G$17,">"&G10)+1 | I10: =IF(H10<=5,"TOP 5","")
A11: Realisable share of stock-out proxy | B11: =Inputs!$C$49 | C11: =Inputs!$E$49 | D11: =N70 | E11: =O70 | F11: =Levers!$D$52 | G11: =ABS(E11-D11) | H11: =COUNTIF($G$5:$G$17,">"&G11)+1 | I11: =IF(H11<=5,"TOP 5","")
A12: Inventory reduction (inv_red) | B12: =Inputs!$C$51 | C12: =Inputs!$E$51 | D12: =P70 | E12: =Q70 | F12: =Levers!$D$52 | G12: =ABS(E12-D12) | H12: =COUNTIF($G$5:$G$17,">"&G12)+1 | I12: =IF(H12<=5,"TOP 5","")
A13: Sales-lift cap | B13: =Inputs!$C$50 | C13: =Inputs!$E$50 | D13: =R70 | E13: =S70 | F13: =Levers!$D$52 | G13: =ABS(E13-D13) | H13: =COUNTIF($G$5:$G$17,">"&G13)+1 | I13: =IF(H13<=5,"TOP 5","")
A14: Planner time saved | B14: =Inputs!$C$55 | C14: =Inputs!$E$55 | D14: =T70 | E14: =U70 | F14: =Levers!$D$52 | G14: =ABS(E14-D14) | H14: =COUNTIF($G$5:$G$17,">"&G14)+1 | I14: =IF(H14<=5,"TOP 5","")
A15: Cost of capital (coc) | B15: =Inputs!$C$26 | C15: =Inputs!$E$26 | D15: =V70 | E15: =W70 | F15: =Levers!$D$52 | G15: =ABS(E15-D15) | H15: =COUNTIF($G$5:$G$17,">"&G15)+1 | I15: =IF(H15<=5,"TOP 5","")
A16: Size or fit return reduction | B16: =Inputs!$C$54 | C16: =Inputs!$E$54 | D16: =X70 | E16: =Y70 | F16: =Levers!$D$52 | G16: =ABS(E16-D16) | H16: =COUNTIF($G$5:$G$17,">"&G16)+1 | I16: =IF(H16<=5,"TOP 5","")
A17: Gross margin (gm) | B17: =Inputs!$C$24 | C17: =Inputs!$E$24 | D17: =Z70 | E17: =AA70 | F17: =Levers!$D$52 | G17: =ABS(E17-D17) | H17: =COUNTIF($G$5:$G$17,">"&G17)+1 | I17: =IF(H17<=5,"TOP 5","")
A18: Ramp row: Y1/Y2/Y3 move together; inputs shown are Y1.
A21: Calculation block (one column per run)
B22: Markdown reduction (md_red) - low | C22: Markdown reduction (md_red) - high | D22: Cost multiplier - low | E22: Cost multiplier - high | F22: Markdown cost share (md_pct) - low | G22: Markdown cost share (md_pct) - high | H22: Adoption ramp Y1-Y3 - low | I22: Adoption ramp Y1-Y3 - high | J22: Lost-sales reduction (ls_red) - low | K22: Lost-sales reduction (ls_red) - high | L22: Overlap haircut - low | M22: Overlap haircut - high | N22: Realisable share of stock-out proxy - low | O22: Realisable share of stock-out proxy - high | P22: Inventory reduction (inv_red) - low | Q22: Inventory reduction (inv_red) - high | R22: Sales-lift cap - low | S22: Sales-lift cap - high | T22: Planner time saved - low | U22: Planner time saved - high | V22: Cost of capital (coc) - low | W22: Cost of capital (coc) - high | X22: Size or fit return reduction - low | Y22: Size or fit return reduction - high | Z22: Gross margin (gm) - low | AA22: Gross margin (gm) - high
A23: Common
A24: VAT divisor (1 + VAT) | B24: =1+Inputs!$D$23 | C24: =1+Inputs!$D$23 | D24: =1+Inputs!$D$23 | E24: =1+Inputs!$D$23 | F24: =1+Inputs!$D$23 | G24: =1+Inputs!$D$23 | H24: =1+Inputs!$D$23 | I24: =1+Inputs!$D$23 | ... AA24: =1+Inputs!$D$23
A25: Net revenue ex VAT | B25: =Inputs!$D$9/B24 | C25: =Inputs!$D$9/C24 | D25: =Inputs!$D$9/D24 | E25: =Inputs!$D$9/E24 | F25: =Inputs!$D$9/F24 | G25: =Inputs!$D$9/G24 | H25: =Inputs!$D$9/H24 | I25: =Inputs!$D$9/I24 | ... AA25: =Inputs!$D$9/AA24
A26: Contribution margin on extra sales | B26: =Inputs!$D$24-Inputs!$D$25 | C26: =Inputs!$D$24-Inputs!$D$25 | D26: =Inputs!$D$24-Inputs!$D$25 | E26: =Inputs!$D$24-Inputs!$D$25 | F26: =Inputs!$D$24-Inputs!$D$25 | G26: =Inputs!$D$24-Inputs!$D$25 | H26: =Inputs!$D$24-Inputs!$D$25 | I26: =Inputs!$D$24-Inputs!$D$25 | ... Y26: =Inputs!$D$24-Inputs!$D$25 | Z26: =Inputs!$C$24-Inputs!$D$25 | AA26: =Inputs!$E$24-Inputs!$D$25
A27: (a) Recovered lost sales from fewer stock-outs
A28: Softline lost demand a year (gross) | B28: =Inputs!$D$16*365*Inputs!$D$49 | C28: =Inputs!$D$16*365*Inputs!$D$49 | D28: =Inputs!$D$16*365*Inputs!$D$49 | E28: =Inputs!$D$16*365*Inputs!$D$49 | F28: =Inputs!$D$16*365*Inputs!$D$49 | G28: =Inputs!$D$16*365*Inputs!$D$49 | H28: =Inputs!$D$16*365*Inputs!$D$49 | I28: =Inputs!$D$16*365*Inputs!$D$49 | ... M28: =Inputs!$D$16*365*Inputs!$D$49 | N28: =Inputs!$D$16*365*Inputs!$C$49 | O28: =Inputs!$D$16*365*Inputs!$E$49 | P28: =Inputs!$D$16*365*Inputs!$D$49 | Q28: =Inputs!$D$16*365*Inputs!$D$49 | R28: =Inputs!$D$16*365*Inputs!$D$49 | S28: =Inputs!$D$16*365*Inputs!$D$49 | T28: =Inputs!$D$16*365*Inputs!$D$49 | U28: =Inputs!$D$16*365*Inputs!$D$49 | V28: =Inputs!$D$16*365*Inputs!$D$49 | W28: =Inputs!$D$16*365*Inputs!$D$49 | ... AA28: =Inputs!$D$16*365*Inputs!$D$49
A29: Hardline lost demand a year (gross) | B29: =B28/Inputs!$D$7*Inputs!$D$8*Inputs!$D$32 | C29: =C28/Inputs!$D$7*Inputs!$D$8*Inputs!$D$32 | D29: =D28/Inputs!$D$7*Inputs!$D$8*Inputs!$D$32 | E29: =E28/Inputs!$D$7*Inputs!$D$8*Inputs!$D$32 | F29: =F28/Inputs!$D$7*Inputs!$D$8*Inputs!$D$32 | G29: =G28/Inputs!$D$7*Inputs!$D$8*Inputs!$D$32 | H29: =H28/Inputs!$D$7*Inputs!$D$8*Inputs!$D$32 | I29: =I28/Inputs!$D$7*Inputs!$D$8*Inputs!$D$32 | ... AA29: =AA28/Inputs!$D$7*Inputs!$D$8*Inputs!$D$32
A30: Total lost demand a year (gross) | B30: =B28+B29 | C30: =C28+C29 | D30: =D28+D29 | E30: =E28+E29 | F30: =F28+F29 | G30: =G28+G29 | H30: =H28+H29 | I30: =I28+I29 | ... AA30: =AA28+AA29
A31: Recovered sales before cap | B31: =B30*Inputs!$D$48 | C31: =C30*Inputs!$D$48 | D31: =D30*Inputs!$D$48 | E31: =E30*Inputs!$D$48 | F31: =F30*Inputs!$D$48 | G31: =G30*Inputs!$D$48 | H31: =H30*Inputs!$D$48 | I31: =I30*Inputs!$D$48 | J31: =J30*Inputs!$C$48 | K31: =K30*Inputs!$E$48 | L31: =L30*Inputs!$D$48 | M31: =M30*Inputs!$D$48 | N31: =N30*Inputs!$D$48 | O31: =O30*Inputs!$D$48 | P31: =P30*Inputs!$D$48 | Q31: =Q30*Inputs!$D$48 | R31: =R30*Inputs!$D$48 | S31: =S30*Inputs!$D$48 | ... AA31: =AA30*Inputs!$D$48
A32: Cap: revenue x total sales lift | B32: =Inputs!$D$6*Inputs!$D$50 | C32: =Inputs!$D$6*Inputs!$D$50 | D32: =Inputs!$D$6*Inputs!$D$50 | E32: =Inputs!$D$6*Inputs!$D$50 | F32: =Inputs!$D$6*Inputs!$D$50 | G32: =Inputs!$D$6*Inputs!$D$50 | H32: =Inputs!$D$6*Inputs!$D$50 | I32: =Inputs!$D$6*Inputs!$D$50 | ... Q32: =Inputs!$D$6*Inputs!$D$50 | R32: =Inputs!$D$6*Inputs!$C$50 | S32: =Inputs!$D$6*Inputs!$E$50 | T32: =Inputs!$D$6*Inputs!$D$50 | U32: =Inputs!$D$6*Inputs!$D$50 | V32: =Inputs!$D$6*Inputs!$D$50 | W32: =Inputs!$D$6*Inputs!$D$50 | X32: =Inputs!$D$6*Inputs!$D$50 | Y32: =Inputs!$D$6*Inputs!$D$50 | Z32: =Inputs!$D$6*Inputs!$D$50 | AA32: =Inputs!$D$6*Inputs!$D$50
A33: Recovered gross sales (lower of the two) | B33: =MIN(B31,B32) | C33: =MIN(C31,C32) | D33: =MIN(D31,D32) | E33: =MIN(E31,E32) | F33: =MIN(F31,F32) | G33: =MIN(G31,G32) | H33: =MIN(H31,H32) | I33: =MIN(I31,I32) | ... AA33: =MIN(AA31,AA32)
A34: (a) Value: recovered sales at contribution margin | B34: =B33/B24*(1-Inputs!$D$11)*B26 | C34: =C33/C24*(1-Inputs!$D$11)*C26 | D34: =D33/D24*(1-Inputs!$D$11)*D26 | E34: =E33/E24*(1-Inputs!$D$11)*E26 | F34: =F33/F24*(1-Inputs!$D$11)*F26 | G34: =G33/G24*(1-Inputs!$D$11)*G26 | H34: =H33/H24*(1-Inputs!$D$11)*H26 | I34: =I33/I24*(1-Inputs!$D$11)*I26 | ... AA34: =AA33/AA24*(1-Inputs!$D$11)*AA26
A35: (b) Working capital released from lower inventory
A36: Stock at cost, ex VAT | B36: =Inputs!$D$12/B24*(1-Inputs!$D$24) | C36: =Inputs!$D$12/C24*(1-Inputs!$D$24) | D36: =Inputs!$D$12/D24*(1-Inputs!$D$24) | E36: =Inputs!$D$12/E24*(1-Inputs!$D$24) | F36: =Inputs!$D$12/F24*(1-Inputs!$D$24) | G36: =Inputs!$D$12/G24*(1-Inputs!$D$24) | H36: =Inputs!$D$12/H24*(1-Inputs!$D$24) | I36: =Inputs!$D$12/I24*(1-Inputs!$D$24) | ... Y36: =Inputs!$D$12/Y24*(1-Inputs!$D$24) | Z36: =Inputs!$D$12/Z24*(1-Inputs!$C$24) | AA36: =Inputs!$D$12/AA24*(1-Inputs!$E$24)
A37: One-off cash release at full adoption (shown separately) | B37: =B36*Inputs!$D$51 | C37: =C36*Inputs!$D$51 | D37: =D36*Inputs!$D$51 | E37: =E36*Inputs!$D$51 | F37: =F36*Inputs!$D$51 | G37: =G36*Inputs!$D$51 | H37: =H36*Inputs!$D$51 | I37: =I36*Inputs!$D$51 | ... O37: =O36*Inputs!$D$51 | P37: =P36*Inputs!$C$51 | Q37: =Q36*Inputs!$E$51 | R37: =R36*Inputs!$D$51 | S37: =S36*Inputs!$D$51 | T37: =T36*Inputs!$D$51 | U37: =U36*Inputs!$D$51 | V37: =V36*Inputs!$D$51 | W37: =W36*Inputs!$D$51 | X37: =X36*Inputs!$D$51 | Y37: =Y36*Inputs!$D$51 | ... AA37: =AA36*Inputs!$D$51
A38: (b) Value: annual carrying saving on released cash | B38: =B37*Inputs!$D$26 | C38: =C37*Inputs!$D$26 | D38: =D37*Inputs!$D$26 | E38: =E37*Inputs!$D$26 | F38: =F37*Inputs!$D$26 | G38: =G37*Inputs!$D$26 | H38: =H37*Inputs!$D$26 | I38: =I37*Inputs!$D$26 | ... U38: =U37*Inputs!$D$26 | V38: =V37*Inputs!$C$26 | W38: =W37*Inputs!$E$26 | X38: =X37*Inputs!$D$26 | Y38: =Y37*Inputs!$D$26 | Z38: =Z37*Inputs!$D$26 | AA38: =AA37*Inputs!$D$26
A39: (c) Markdown and ageing write-down avoided
A40: Markdown and write-down cost a year | B40: =B25*Inputs!$D$28 | C40: =C25*Inputs!$D$28 | D40: =D25*Inputs!$D$28 | E40: =E25*Inputs!$D$28 | F40: =F25*Inputs!$C$28 | G40: =G25*Inputs!$E$28 | H40: =H25*Inputs!$D$28 | I40: =I25*Inputs!$D$28 | J40: =J25*Inputs!$D$28 | K40: =K25*Inputs!$D$28 | L40: =L25*Inputs!$D$28 | M40: =M25*Inputs!$D$28 | N40: =N25*Inputs!$D$28 | O40: =O25*Inputs!$D$28 | ... AA40: =AA25*Inputs!$D$28
A41: Cross-check: stock over 180 days x clearance discount, ex VAT | B41: =Inputs!$D$15/B24*Inputs!$D$29 | C41: =Inputs!$D$15/C24*Inputs!$D$29 | D41: =Inputs!$D$15/D24*Inputs!$D$29 | E41: =Inputs!$D$15/E24*Inputs!$D$29 | F41: =Inputs!$D$15/F24*Inputs!$D$29 | G41: =Inputs!$D$15/G24*Inputs!$D$29 | H41: =Inputs!$D$15/H24*Inputs!$D$29 | I41: =Inputs!$D$15/I24*Inputs!$D$29 | ... AA41: =Inputs!$D$15/AA24*Inputs!$D$29
A42: (c) Value: markdown and write-down avoided | B42: =B40*Inputs!$C$52 | C42: =C40*Inputs!$E$52 | D42: =D40*Inputs!$D$52 | E42: =E40*Inputs!$D$52 | F42: =F40*Inputs!$D$52 | G42: =G40*Inputs!$D$52 | H42: =H40*Inputs!$D$52 | I42: =I40*Inputs!$D$52 | J42: =J40*Inputs!$D$52 | K42: =K40*Inputs!$D$52 | ... AA42: =AA40*Inputs!$D$52
A43: (d) Size-curve improvement: fewer size or fit returns
...

Sheet Per-brand
A1: Per-brand view - base-case annual benefit at full adoption, split by brand
A2: Brand data (blue) from 03 summary and stock-out tables. Split keys: (a) softline by stock-out proxy USD/day, hardline by gross revenue; (b) by stock value; (c) by net revenue; (d) by Namshi size or fit returns; (e) by gross revenue. The overlap haircut is applied per brand. Totals tie to Levers base.
A4: Brand | B4: Segment | C4: Gross USD (03) | D4: Net USD (03) | E4: Stock at ASP (03) | F4: Stock-out proxy USD/day (03) | G4: Size/fit returns USD (03) | H4: (a) | I4: (b) | J4: (c) | K4: (d) | L4: (e) | M4: Overlap | N4: Total benefit | O4: Share of total | P4: Benefit % of brand gross
A5: U.S. Polo Assn. | B5: Soft | C5: 6120000 | D5: 5320000 | E5: 1650000 | F5: 3276 | G5: 388000 | H5: =Levers!$D$16*(Levers!$D$10/Levers!$D$12)*F5/SUMIF($B$5:$B$22,"Soft",$F$5:$F$22) | I5: =Levers!$D$20*E5/$E$23 | J5: =Levers!$D$24*D5/$D$23 | K5: =Levers!$D$27*G5/$G$23 | L5: =Levers!$D$29*C5/$C$23 | M5: =-(H5+I5+J5)*Inputs!$D$43 | N5: =SUM(H5:M5) | O5: =N5/$N$23 | P5: =IF(C5>0,N5/C5,0)
A6: French Connection | B6: Soft | C6: 681000 | D6: 467000 | E6: 789000 | F6: 879 | G6: 127000 | H6: =Levers!$D$16*(Levers!$D$10/Levers!$D$12)*F6/SUMIF($B$5:$B$22,"Soft",$F$5:$F$22) | I6: =Levers!$D$20*E6/$E$23 | J6: =Levers!$D$24*D6/$D$23 | K6: =Levers!$D$27*G6/$G$23 | L6: =Levers!$D$29*C6/$C$23 | M6: =-(H6+I6+J6)*Inputs!$D$43 | N6: =SUM(H6:M6) | O6: =N6/$N$23 | P6: =IF(C6>0,N6/C6,0)
A7: Campus | B7: Soft | C7: 668000 | D7: 542000 | E7: 430000 | F7: 786 | G7: 68000 | H7: =Levers!$D$16*(Levers!$D$10/Levers!$D$12)*F7/SUMIF($B$5:$B$22,"Soft",$F$5:$F$22) | I7: =Levers!$D$20*E7/$E$23 | J7: =Levers!$D$24*D7/$D$23 | K7: =Levers!$D$27*G7/$G$23 | L7: =Levers!$D$29*C7/$C$23 | M7: =-(H7+I7+J7)*Inputs!$D$43 | N7: =SUM(H7:M7) | O7: =N7/$N$23 | P7: =IF(C7>0,N7/C7,0)
A8: Penti | B8: Soft | C8: 403000 | D8: 363000 | E8: 343000 | F8: 545 | G8: 19000 | H8: =Levers!$D$16*(Levers!$D$10/Levers!$D$12)*F8/SUMIF($B$5:$B$22,"Soft",$F$5:$F$22) | I8: =Levers!$D$20*E8/$E$23 | J8: =Levers!$D$24*D8/$D$23 | K8: =Levers!$D$27*G8/$G$23 | L8: =Levers!$D$29*C8/$C$23 | M8: =-(H8+I8+J8)*Inputs!$D$43 | N8: =SUM(H8:M8) | O8: =N8/$N$23 | P8: =IF(C8>0,N8/C8,0)
A9: Keds | B9: Soft | C9: 138000 | D9: 96000 | E9: 500000 | F9: 336 | G9: 30000 | H9: =Levers!$D$16*(Levers!$D$10/Levers!$D$12)*F9/SUMIF($B$5:$B$22,"Soft",$F$5:$F$22) | I9: =Levers!$D$20*E9/$E$23 | J9: =Levers!$D$24*D9/$D$23 | K9: =Levers!$D$27*G9/$G$23 | L9: =Levers!$D$29*C9/$C$23 | M9: =-(H9+I9+J9)*Inputs!$D$43 | N9: =SUM(H9:M9) | O9: =N9/$N$23 | P9: =IF(C9>0,N9/C9,0)
A10: Vero Moda | B10: Soft | C10: 138000 | D10: 89000 | E10: 197000 | F10: 217 | G10: 24000 | H10: =Levers!$D$16*(Levers!$D$10/Levers!$D$12)*F10/SUMIF($B$5:$B$22,"Soft",$F$5:$F$22) | I10: =Levers!$D$20*E10/$E$23 | J10: =Levers!$D$24*D10/$D$23 | K10: =Levers!$D$27*G10/$G$23 | L10: =Levers!$D$29*C10/$C$23 | M10: =-(H10+I10+J10)*Inputs!$D$43 | N10: =SUM(H10:M10) | O10: =N10/$N$23 | P10: =IF(C10>0,N10/C10,0)
A11: Puma | B11: Soft | C11: 109000 | D11: 99000 | E11: 154000 | F11: 400 | G11: 0 | H11: =Levers!$D$16*(Levers!$D$10/Levers!$D$12)*F11/SUMIF($B$5:$B$22,"Soft",$F$5:$F$22) | I11: =Levers!$D$20*E11/$E$23 | J11: =Levers!$D$24*D11/$D$23 | K11: =Levers!$D$27*G11/$G$23 | L11: =Levers!$D$29*C11/$C$23 | M11: =-(H11+I11+J11)*Inputs!$D$43 | N11: =SUM(H11:M11) | O11: =N11/$N$23 | P11: =IF(C11>0,N11/C11,0)
A12: Nautica | B12: Soft | C12: 108000 | D12: 86000 | E12: 2000 | F12: 54 | G12: 14000 | H12: =Levers!$D$16*(Levers!$D$10/Levers!$D$12)*F12/SUMIF($B$5:$B$22,"Soft",$F$5:$F$22) | I12: =Levers!$D$20*E12/$E$23 | J12: =Levers!$D$24*D12/$D$23 | K12: =Levers!$D$27*G12/$G$23 | L12: =Levers!$D$29*C12/$C$23 | M12: =-(H12+I12+J12)*Inputs!$D$43 | N12: =SUM(H12:M12) | O12: =N12/$N$23 | P12: =IF(C12>0,N12/C12,0)
A13: Cardio Bunny | B13: Soft | C13: 93000 | D13: 72000 | E13: 161000 | F13: 172 | G13: 14000 | H13: =Levers!$D$16*(Levers!$D$10/Levers!$D$12)*F13/SUMIF($B$5:$B$22,"Soft",$F$5:$F$22) | I13: =Levers!$D$20*E13/$E$23 | J13: =Levers!$D$24*D13/$D$23 | K13: =Levers!$D$27*G13/$G$23 | L13: =Levers!$D$29*C13/$C$23 | M13: =-(H13+I13+J13)*Inputs!$D$43 | N13: =SUM(H13:M13) | O13: =N13/$N$23 | P13: =IF(C13>0,N13/C13,0)
A14: Nutricook | B14: Hard | C14: 1870000 | D14: 1870000 | E14: 534000 | F14: 0 | G14: 0 | H14: =Levers!$D$16*(1-(Levers!$D$10/Levers!$D$12))*C14/SUMIF($B$5:$B$22,"Hard",$C$5:$C$22) | I14: =Levers!$D$20*E14/$E$23 | J14: =Levers!$D$24*D14/$D$23 | K14: =Levers!$D$27*G14/$G$23 | L14: =Levers!$D$29*C14/$C$23 | M14: =-(H14+I14+J14)*Inputs!$D$43 | N14: =SUM(H14:M14) | O14: =N14/$N$23 | P14: =IF(C14>0,N14/C14,0)
A15: GTPlayer | B15: Hard | C15: 1520000 | D15: 1510000 | E15: 278000 | F15: 0 | G15: 0 | H15: =Levers!$D$16*(1-(Levers!$D$10/Levers!$D$12))*C15/SUMIF($B$5:$B$22,"Hard",$C$5:$C$22) | I15: =Levers!$D$20*E15/$E$23 | J15: =Levers!$D$24*D15/$D$23 | K15: =Levers!$D$27*G15/$G$23 | L15: =Levers!$D$29*C15/$C$23 | M15: =-(H15+I15+J15)*Inputs!$D$43 | N15: =SUM(H15:M15) | O15: =N15/$N$23 | P15: =IF(C15>0,N15/C15,0)
A16: NutriBullet | B16: Hard | C16: 574000 | D16: 574000 | E16: 353000 | F16: 0 | G16: 0 | H16: =Levers!$D$16*(1-(Levers!$D$10/Levers!$D$12))*C16/SUMIF($B$5:$B$22,"Hard",$C$5:$C$22) | I16: =Levers!$D$20*E16/$E$23 | J16: =Levers!$D$24*D16/$D$23 | K16: =Levers!$D$27*G16/$G$23 | L16: =Levers!$D$29*C16/$C$23 | M16: =-(H16+I16+J16)*Inputs!$D$43 | N16: =SUM(H16:M16) | O16: =N16/$N$23 | P16: =IF(C16>0,N16/C16,0)
A17: Carote | B17: Hard | C17: 572000 | D17: 557000 | E17: 644000 | F17: 0 | G17: 0 | H17: =Levers!$D$16*(1-(Levers!$D$10/Levers!$D$12))*C17/SUMIF($B$5:$B$22,"Hard",$C$5:$C$22) | I17: =Levers!$D$20*E17/$E$23 | J17: =Levers!$D$24*D17/$D$23 | K17: =Levers!$D$27*G17/$G$23 | L17: =Levers!$D$29*C17/$C$23 | M17: =-(H17+I17+J17)*Inputs!$D$43 | N17: =SUM(H17:M17) | O17: =N17/$N$23 | P17: =IF(C17>0,N17/C17,0)
A18: Bergner | B18: Hard | C18: 259000 | D18: 255000 | E18: 333000 | F18: 0 | G18: 0 | H18: =Levers!$D$16*(1-(Levers!$D$10/Levers!$D$12))*C18/SUMIF($B$5:$B$22,"Hard",$C$5:$C$22) | I18: =Levers!$D$20*E18/$E$23 | J18: =Levers!$D$24*D18/$D$23 | K18: =Levers!$D$27*G18/$G$23 | L18: =Levers!$D$29*C18/$C$23 | M18: =-(H18+I18+J18)*Inputs!$D$43 | N18: =SUM(H18:M18) | O18: =N18/$N$23 | P18: =IF(C18>0,N18/C18,0)
A19: Dowinx | B19: Hard | C19: 108000 | D19: 108000 | E19: 0 | F19: 0 | G19: 0 | H19: =Levers!$D$16*(1-(Levers!$D$10/Levers!$D$12))*C19/SUMIF($B$5:$B$22,"Hard",$C$5:$C$22) | I19: =Levers!$D$20*E19/$E$23 | J19: =Levers!$D$24*D19/$D$23 | K19: =Levers!$D$27*G19/$G$23 | L19: =Levers!$D$29*C19/$C$23 | M19: =-(H19+I19+J19)*Inputs!$D$43 | N19: =SUM(H19:M19) | O19: =N19/$N$23 | P19: =IF(C19>0,N19/C19,0)
A20: Tower | B20: Hard | C20: 17000 | D20: 17000 | E20: 51000 | F20: 0 | G20: 0 | H20: =Levers!$D$16*(1-(Levers!$D$10/Levers!$D$12))*C20/SUMIF($B$5:$B$22,"Hard",$C$5:$C$22) | I20: =Levers!$D$20*E20/$E$23 | J20: =Levers!$D$24*D20/$D$23 | K20: =Levers!$D$27*G20/$G$23 | L20: =Levers!$D$29*C20/$C$23 | M20: =-(H20+I20+J20)*Inputs!$D$43 | N20: =SUM(H20:M20) | O20: =N20/$N$23 | P20: =IF(C20>0,N20/C20,0)
A21: Qubo | B21: Hard | C21: 8000 | D21: 8000 | E21: 47000 | F21: 0 | G21: 0 | H21: =Levers!$D$16*(1-(Levers!$D$10/Levers!$D$12))*C21/SUMIF($B$5:$B$22,"Hard",$C$5:$C$22) | I21: =Levers!$D$20*E21/$E$23 | J21: =Levers!$D$24*D21/$D$23 | K21: =Levers!$D$27*G21/$G$23 | L21: =Levers!$D$29*C21/$C$23 | M21: =-(H21+I21+J21)*Inputs!$D$43 | N21: =SUM(H21:M21) | O21: =N21/$N$23 | P21: =IF(C21>0,N21/C21,0)
A22: Nuwey | B22: Hard | C22: 2000 | D22: 2000 | E22: 7000 | F22: 0 | G22: 0 | H22: =Levers!$D$16*(1-(Levers!$D$10/Levers!$D$12))*C22/SUMIF($B$5:$B$22,"Hard",$C$5:$C$22) | I22: =Levers!$D$20*E22/$E$23 | J22: =Levers!$D$24*D22/$D$23 | K22: =Levers!$D$27*G22/$G$23 | L22: =Levers!$D$29*C22/$C$23 | M22: =-(H22+I22+J22)*Inputs!$D$43 | N22: =SUM(H22:M22) | O22: =N22/$N$23 | P22: =IF(C22>0,N22/C22,0)
A23: Total | C23: =SUM(C5:C22) | D23: =SUM(D5:D22) | E23: =SUM(E5:E22) | F23: =SUM(F5:F22) | G23: =SUM(G5:G22) | H23: =SUM(H5:H22) | I23: =SUM(I5:I22) | J23: =SUM(J5:J22) | ... O23: =SUM(O5:O22) | P23: =N23/C23
A24: Check: Levers base annual benefit | N24: =Levers!$D$33
A26: Summary
A27: U.S. Polo Assn. | C27: =O5
A28: Other softline brands (excl Cardio Bunny) | C28: =SUMIF($B$5:$B$22,"Soft",$O$5:$O$22)-O5-O13
A29: Cardio Bunny | C29: =O13
A30: Hardline brands | C30: =SUMIF($B$5:$B$22,"Hard",$O$5:$O$22)
A32: Stock-out proxy is softline only (03 caveat 9); Puma has no Namshi size/fit figure (n/a in 03), set to 0.
